[2025-02-08T14:17:07.012+0000] {local_task_job_runner.py:123} INFO - ::group::Pre task execution logs
[2025-02-08T14:17:07.070+0000] {taskinstance.py:2613} INFO - Dependencies all met for dep_context=non-requeueable deps ti=<TaskInstance: etl.raw_kaggle_source manual__2025-02-08T14:12:01.371026+00:00 [queued]>
[2025-02-08T14:17:07.103+0000] {taskinstance.py:2613} INFO - Dependencies all met for dep_context=requeueable deps ti=<TaskInstance: etl.raw_kaggle_source manual__2025-02-08T14:12:01.371026+00:00 [queued]>
[2025-02-08T14:17:07.104+0000] {taskinstance.py:2866} INFO - Starting attempt 2 of 4
[2025-02-08T14:17:07.139+0000] {taskinstance.py:2889} INFO - Executing <Task(BashOperator): raw_kaggle_source> on 2025-02-08 14:12:01.371026+00:00
[2025-02-08T14:17:07.153+0000] {warnings.py:112} WARNING - /home/***/.local/lib/python3.12/site-packages/***/task/task_runner/standard_task_runner.py:70: DeprecationWarning: This process (pid=191) is multi-threaded, use of fork() may lead to deadlocks in the child.
  pid = os.fork()

[2025-02-08T14:17:07.163+0000] {standard_task_runner.py:72} INFO - Started process 194 to run task
[2025-02-08T14:17:07.156+0000] {standard_task_runner.py:104} INFO - Running: ['***', 'tasks', 'run', 'etl', 'raw_kaggle_source', 'manual__2025-02-08T14:12:01.371026+00:00', '--job-id', '20', '--raw', '--subdir', 'DAGS_FOLDER/etl.py', '--cfg-path', '/tmp/tmpc4zu3963']
[2025-02-08T14:17:07.164+0000] {standard_task_runner.py:105} INFO - Job 20: Subtask raw_kaggle_source
[2025-02-08T14:17:07.320+0000] {task_command.py:467} INFO - Running <TaskInstance: etl.raw_kaggle_source manual__2025-02-08T14:12:01.371026+00:00 [running]> on host a158e10e7925
[2025-02-08T14:17:07.504+0000] {taskinstance.py:3132} INFO - Exporting env vars: AIRFLOW_CTX_DAG_OWNER='etl' AIRFLOW_CTX_DAG_ID='etl' AIRFLOW_CTX_TASK_ID='raw_kaggle_source' AIRFLOW_CTX_EXECUTION_DATE='2025-02-08T14:12:01.371026+00:00' AIRFLOW_CTX_TRY_NUMBER='2' AIRFLOW_CTX_DAG_RUN_ID='manual__2025-02-08T14:12:01.371026+00:00'
[2025-02-08T14:17:07.505+0000] {taskinstance.py:731} INFO - ::endgroup::
[2025-02-08T14:17:07.554+0000] {subprocess.py:78} INFO - Tmp dir root location: /tmp
[2025-02-08T14:17:07.556+0000] {subprocess.py:88} INFO - Running command: ['/usr/bin/bash', '-c', 'docker exec spark-master /opt/spark/bin/spark-submit   --master spark://spark-master:7077   --conf spark.executor.memory=2g   --verbose   /opt/spark/ETL/raw/kaggle_source.py']
[2025-02-08T14:17:07.584+0000] {subprocess.py:99} INFO - Output:
[2025-02-08T14:17:07.599+0000] {subprocess.py:106} INFO - Cannot connect to the Docker daemon at unix:///var/run/docker.sock. Is the docker daemon running?
[2025-02-08T14:17:07.601+0000] {subprocess.py:110} INFO - Command exited with return code 1
[2025-02-08T14:17:07.614+0000] {taskinstance.py:3311} ERROR - Task failed with exception
Traceback (most recent call last):
  File "/home/airflow/.local/lib/python3.12/site-packages/airflow/models/taskinstance.py", line 767, in _execute_task
    result = _execute_callable(context=context, **execute_callable_kwargs)
             ^^^^^^^^^^^^^^^^^^^^^^^^^^^^^^^^^^^^^^^^^^^^^^^^^^^^^^^^^^^^^
  File "/home/airflow/.local/lib/python3.12/site-packages/airflow/models/taskinstance.py", line 733, in _execute_callable
    return ExecutionCallableRunner(
           ^^^^^^^^^^^^^^^^^^^^^^^^
  File "/home/airflow/.local/lib/python3.12/site-packages/airflow/utils/operator_helpers.py", line 252, in run
    return self.func(*args, **kwargs)
           ^^^^^^^^^^^^^^^^^^^^^^^^^^
  File "/home/airflow/.local/lib/python3.12/site-packages/airflow/models/baseoperator.py", line 422, in wrapper
    return func(self, *args, **kwargs)
           ^^^^^^^^^^^^^^^^^^^^^^^^^^^
  File "/home/airflow/.local/lib/python3.12/site-packages/airflow/operators/bash.py", line 276, in execute
    raise AirflowException(
airflow.exceptions.AirflowException: Bash command failed. The command returned a non-zero exit code 1.
[2025-02-08T14:17:07.625+0000] {taskinstance.py:1225} INFO - Marking task as UP_FOR_RETRY. dag_id=etl, task_id=raw_kaggle_source, run_id=manual__2025-02-08T14:12:01.371026+00:00, execution_date=20250208T141201, start_date=20250208T141707, end_date=20250208T141707
[2025-02-08T14:17:07.652+0000] {taskinstance.py:340} INFO - ::group::Post task execution logs
[2025-02-08T14:17:07.654+0000] {standard_task_runner.py:124} ERROR - Failed to execute job 20 for task raw_kaggle_source (Bash command failed. The command returned a non-zero exit code 1.; 194)
Traceback (most recent call last):
  File "/home/airflow/.local/lib/python3.12/site-packages/airflow/task/task_runner/standard_task_runner.py", line 117, in _start_by_fork
    ret = args.func(args, dag=self.dag)
          ^^^^^^^^^^^^^^^^^^^^^^^^^^^^^
  File "/home/airflow/.local/lib/python3.12/site-packages/airflow/cli/cli_config.py", line 49, in command
    return func(*args, **kwargs)
           ^^^^^^^^^^^^^^^^^^^^^
  File "/home/airflow/.local/lib/python3.12/site-packages/airflow/utils/cli.py", line 116, in wrapper
    return f(*args, **kwargs)
           ^^^^^^^^^^^^^^^^^^
  File "/home/airflow/.local/lib/python3.12/site-packages/airflow/cli/commands/task_command.py", line 483, in task_run
    task_return_code = _run_task_by_selected_method(args, _dag, ti)
                       ^^^^^^^^^^^^^^^^^^^^^^^^^^^^^^^^^^^^^^^^^^^^
  File "/home/airflow/.local/lib/python3.12/site-packages/airflow/cli/commands/task_command.py", line 256, in _run_task_by_selected_method
    return _run_raw_task(args, ti)
           ^^^^^^^^^^^^^^^^^^^^^^^
  File "/home/airflow/.local/lib/python3.12/site-packages/airflow/cli/commands/task_command.py", line 341, in _run_raw_task
    return ti._run_raw_task(
           ^^^^^^^^^^^^^^^^^
  File "/home/airflow/.local/lib/python3.12/site-packages/airflow/utils/session.py", line 97, in wrapper
    return func(*args, session=session, **kwargs)
           ^^^^^^^^^^^^^^^^^^^^^^^^^^^^^^^^^^^^^^
  File "/home/airflow/.local/lib/python3.12/site-packages/airflow/models/taskinstance.py", line 3005, in _run_raw_task
    return _run_raw_task(
           ^^^^^^^^^^^^^^
  File "/home/airflow/.local/lib/python3.12/site-packages/airflow/models/taskinstance.py", line 273, in _run_raw_task
    TaskInstance._execute_task_with_callbacks(
  File "/home/airflow/.local/lib/python3.12/site-packages/airflow/models/taskinstance.py", line 3159, in _execute_task_with_callbacks
    result = self._execute_task(context, task_orig)
             ^^^^^^^^^^^^^^^^^^^^^^^^^^^^^^^^^^^^^^
  File "/home/airflow/.local/lib/python3.12/site-packages/airflow/models/taskinstance.py", line 3183, in _execute_task
    return _execute_task(self, context, task_orig)
           ^^^^^^^^^^^^^^^^^^^^^^^^^^^^^^^^^^^^^^^
  File "/home/airflow/.local/lib/python3.12/site-packages/airflow/models/taskinstance.py", line 767, in _execute_task
    result = _execute_callable(context=context, **execute_callable_kwargs)
             ^^^^^^^^^^^^^^^^^^^^^^^^^^^^^^^^^^^^^^^^^^^^^^^^^^^^^^^^^^^^^
  File "/home/airflow/.local/lib/python3.12/site-packages/airflow/models/taskinstance.py", line 733, in _execute_callable
    return ExecutionCallableRunner(
           ^^^^^^^^^^^^^^^^^^^^^^^^
  File "/home/airflow/.local/lib/python3.12/site-packages/airflow/utils/operator_helpers.py", line 252, in run
    return self.func(*args, **kwargs)
           ^^^^^^^^^^^^^^^^^^^^^^^^^^
  File "/home/airflow/.local/lib/python3.12/site-packages/airflow/models/baseoperator.py", line 422, in wrapper
    return func(self, *args, **kwargs)
           ^^^^^^^^^^^^^^^^^^^^^^^^^^^
  File "/home/airflow/.local/lib/python3.12/site-packages/airflow/operators/bash.py", line 276, in execute
    raise AirflowException(
airflow.exceptions.AirflowException: Bash command failed. The command returned a non-zero exit code 1.
[2025-02-08T14:17:07.719+0000] {local_task_job_runner.py:266} INFO - Task exited with return code 1
[2025-02-08T14:17:07.742+0000] {taskinstance.py:3895} INFO - 0 downstream tasks scheduled from follow-on schedule check
[2025-02-08T14:17:07.746+0000] {local_task_job_runner.py:245} INFO - ::endgroup::
